Workbook

Sheet Inputs
B2: ASME B31.3 Piping 3D Multi-Element FEA Solver
B3: Edit values in yellow cells. Calculations update automatically in all sheets.
B5: 1. MATERIAL PROPERTIES | J5: 6. GLOBAL DESIGN LOADS
B6: Material ID | C6: E (Pa) | D6: G (Pa) | E6: alpha (1/°C) | F6: Yield Strength (Pa) | G6: Sc (Pa) | H6: Sh (Pa) | J6: Parameter Name | K6: Value | L6: Unit
B7: mat1 | C7: 200000000000 | D7: 77000000000 | E7: 1.2e-05 | F7: 250000000 | G7: 137900000 | H7: 137900000 | J7: global_gravity_x | K7: 0 | L7: m/s²
J8: global_gravity_y | K8: -9.81 | L8: m/s²
J9: global_gravity_z | K9: 0 | L9: m/s²
B10: 2. SECTION PROPERTIES | J10: global_internal_pressure | K10: 2000000 | L10: Pa
B11: Section ID | C11: Outer Diameter (m) | D11: Wall Thickness (m) | E11: Type | F11: Fluid Density (kg/m³) | G11: Insulation Thickness (m) | H11: Insulation Density (kg/m³) | J11: global_temperature_change | K11: 120 | L11: °C
B12: sec1 | C12: 0.1143 | D12: 0.00602 | E12: pipe | F12: 1000 | G12: 0.025 | H12: 200
B15: 3. NODES COORDINATES
B16: Node ID | C16: X (m) | D16: Y (m) | E16: Z (m)
B17: 0 | C17: 0 | D17: 0 | E17: 0
B18: 1 | C18: 3 | D18: 0 | E18: 0
B19: 2 | C19: 3 | D19: 3 | E19: 0
B20: 3 | C20: 5 | D20: 3 | E20: 0
B21: 4 | C21: 3 | D21: 3 | E21: 2
B22: 5
B23: 6
B24: 7
B27: 4. ELEMENTS CONNECTIVITY
B28: Element ID | C28: Node A | D28: Node B | E28: Type | F28: Bend Radius (m) | G28: Material ID | H28: Section ID
B29: 0 | C29: 0 | D29: 1 | E29: pipe | G29: mat1 | H29: sec1
B30: 1 | C30: 1 | D30: 2 | E30: bend | F30: 0.17145 | G30: mat1 | H30: sec1
B31: 2 | C31: 2 | D31: 3 | E31: pipe | G31: mat1 | H31: sec1
B32: 3 | C32: 2 | D32: 4 | E32: pipe | G32: mat1 | H32: sec1
B33: 4 | E33: pipe | G33: mat1 | H33: sec1
B34: 5 | E34: pipe | G34: mat1 | H34: sec1
B35: 6 | E35: pipe | G35: mat1 | H35: sec1
B38: 5. NODAL BOUNDARY CONDITIONS
B39: Node ID | C39: tx | D39: ty | E39: tz | F39: rx | G39: ry | H39: rz
B40: 0 | C40: TRUE | D40: TRUE | E40: TRUE | F40: TRUE | G40: TRUE | H40: TRUE
B41: 3 | D41: 50000
B42: 4 | C42: TRUE | E42: TRUE
B43: 1
B44: 2
B45: 5
B46: 6
B47: 7

Sheet Element_Stiffness
A1: 3D Finite Element Local & Global Stiffness Matrices
B4: ELEMENT 0 ANALYSIS BLOCK
B5: Node A ID | C5: =Inputs!C29 | D5: Node B ID | E5: =Inputs!D29
B6: Is Active? | C6: =AND(C5<>"",E5<>"")
B7: Node A Coord | C7: =IF(C6,VLOOKUP(C5,Inputs!$B$17:$E$24,2,FALSE),0.0) | D7: =IF(C6,VLOOKUP(C5,Inputs!$B$17:$E$24,3,FALSE),0.0) | E7: =IF(C6,VLOOKUP(C5,Inputs!$B$17:$E$24,4,FALSE),0.0) | F7: Node B Coord | G7: =IF(C6,VLOOKUP(E5,Inputs!$B$17:$E$24,2,FALSE),0.0) | H7: =IF(C6,VLOOKUP(E5,Inputs!$B$17:$E$24,3,FALSE),0.0) | I7: =IF(C6,VLOOKUP(E5,Inputs!$B$17:$E$24,4,FALSE),0.0)
B8: deltas dx,dy,dz | C8: =G7-C7 | D8: =H7-D7 | E8: =I7-E7 | F8: Length L | G8: =IF(C6,SQRT(C8^2+D8^2+E8^2),1.0)
B9: dir cosines lx,my,nz | C9: =C8/G8 | D9: =D8/G8 | E9: =E8/G8 | F9: D_is_zero | G9: =AND(ABS(C9)<1E-5,ABS(D9)<1E-5) | H9: D | I9: =SQRT(C9^2+D9^2) | L9: ROTATION MATRIX lambda
B10: Material E, G, alpha | C10: =VLOOKUP(Inputs!G29,Inputs!$B$7:$H$8,2,FALSE) | D10: =VLOOKUP(Inputs!G29,Inputs!$B$7:$H$8,3,FALSE) | E10: =VLOOKUP(Inputs!G29,Inputs!$B$7:$H$8,4,FALSE) | L10: =C9 | M10: =D9 | N10: =E9
B11: Section OD, t | C11: =VLOOKUP(Inputs!H29,Inputs!$B$12:$H$13,2,FALSE) | D11: =VLOOKUP(Inputs!H29,Inputs!$B$12:$H$13,3,FALSE) | L11: =IF(G9,0,-D9/I9) | M11: =IF(G9,IF(E9>0,1,-1),C9/I9) | N11: 0
B12: ro, ri | C12: =C11/2 | D12: =C12-D11 | E12: Area A | F12: =PI()*(C12^2-D12^2) | L12: =IF(G9,IF(E9>0,-1,1),-C9*E9/I9) | M12: =IF(G9,0,-D9*E9/I9) | N12: =IF(G9,0,I9)
B13: Inertia I, J | C13: =(PI()/4)*(C12^4-D12^4) | D13: =C13*2 | E13: Flex Factor k | F13: =IF(Inputs!E29="bend",IF(Inputs!F29<>"",MAX(1.0,1.65/((D11*Inputs!F29)/(((C11-D11)/2)^2))),1.0),1.0)
D14: =IF(C6,$C$10*$F$12/$G$8,0) | E14: 0 | F14: 0 | G14: 0 | H14: 0 | I14: 0 | J14: =-D14 | K14: 0 | L14: 0 | M14: 0 | N14: 0 | O14: 0 | P14: =L10 | Q14: =M10 | R14: =N10 | S14: 0 | T14: 0 | U14: 0 | V14: 0 | W14: 0 | X14: 0 | Y14: 0 | Z14: 0 | AA14: 0 | AG14: =INDEX(Global_Solver!$BC$5:$BC$52, 6*C5+1, 1) | AH14: =SUMPRODUCT(P14:AA14, AG14:AG25) | AI14: =SUMPRODUCT(D14:O14, AH14:AH25)-B26
D15: 0 | E15: =IF(C6,=(12*$C$10*($C$13/$F$13))/($G$8^3),0) | F15: 0 | G15: 0 | H15: 0 | I15: =IF(C6,=(6*$C$10*($C$13/$F$13))/($G$8^2),0) | J15: 0 | K15: =-E15 | L15: 0 | M15: 0 | N15: 0 | O15: =I15 | P15: =L11 | Q15: =M11 | R15: =N11 | S15: 0 | T15: 0 | U15: 0 | V15: 0 | W15: 0 | X15: 0 | Y15: 0 | Z15: 0 | AA15: 0 | AG15: =INDEX(Global_Solver!$BC$5:$BC$52, 6*C5+2, 1) | AH15: =SUMPRODUCT(P15:AA15, AG14:AG25) | AI15: =SUMPRODUCT(D15:O15, AH14:AH25)-B27
D16: 0 | E16: 0 | F16: =IF(C6,=(12*$C$10*($C$13/$F$13))/($G$8^3),0) | G16: 0 | H16: =IF(C6,-=(6*$C$10*($C$13/$F$13))/($G$8^2),0) | I16: 0 | J16: 0 | K16: 0 | L16: =-F16 | M16: 0 | N16: =H16 | O16: 0 | P16: =L12 | Q16: =M12 | R16: =N12 | S16: 0 | T16: 0 | U16: 0 | V16: 0 | W16: 0 | X16: 0 | Y16: 0 | Z16: 0 | AA16: 0 | AG16: =INDEX(Global_Solver!$BC$5:$BC$52, 6*C5+3, 1) | AH16: =SUMPRODUCT(P16:AA16, AG14:AG25) | AI16: =SUMPRODUCT(D16:O16, AH14:AH25)-B28
D17: 0 | E17: 0 | F17: 0 | G17: =IF(C6,$D$10*$D$13/$G$8,0) | H17: 0 | I17: 0 | J17: 0 | K17: 0 | L17: 0 | M17: =-G17 | N17: 0 | O17: 0 | P17: 0 | Q17: 0 | R17: 0 | S17: =L10 | T17: =M10 | U17: =N10 | V17: 0 | W17: 0 | X17: 0 | Y17: 0 | Z17: 0 | AA17: 0 | AG17: =INDEX(Global_Solver!$BC$5:$BC$52, 6*C5+4, 1) | AH17: =SUMPRODUCT(P17:AA17, AG14:AG25) | AI17: =SUMPRODUCT(D17:O17, AH14:AH25)-B29
D18: 0 | E18: 0 | F18: =H16 | G18: 0 | H18: =IF(C6,=(4*$C$10*($C$13/$F$13))/$G$8,0) | I18: 0 | J18: 0 | K18: 0 | L18: =-H16 | M18: 0 | N18: =IF(C6,=(2*$C$10*($C$13/$F$13))/$G$8,0) | O18: 0 | P18: 0 | Q18: 0 | R18: 0 | S18: =L11 | T18: =M11 | U18: =N11 | V18: 0 | W18: 0 | X18: 0 | Y18: 0 | Z18: 0 | AA18: 0 | AG18: =INDEX(Global_Solver!$BC$5:$BC$52, 6*C5+5, 1) | AH18: =SUMPRODUCT(P18:AA18, AG14:AG25) | AI18: =SUMPRODUCT(D18:O18, AH14:AH25)-B30
D19: 0 | E19: =I15 | F19: 0 | G19: 0 | H19: 0 | I19: =IF(C6,=(4*$C$10*($C$13/$F$13))/$G$8,0) | J19: 0 | K19: =-I15 | L19: 0 | M19: 0 | N19: 0 | O19: =IF(C6,=(2*$C$10*($C$13/$F$13))/$G$8,0) | P19: 0 | Q19: 0 | R19: 0 | S19: =L12 | T19: =M12 | U19: =N12 | V19: 0 | W19: 0 | X19: 0 | Y19: 0 | Z19: 0 | AA19: 0 | AG19: =INDEX(Global_Solver!$BC$5:$BC$52, 6*C5+6, 1) | AH19: =SUMPRODUCT(P19:AA19, AG14:AG25) | AI19: =SUMPRODUCT(D19:O19, AH14:AH25)-B31
D20: =J14 | E20: 0 | F20: 0 | G20: 0 | H20: 0 | I20: 0 | J20: =-J14 | K20: 0 | L20: 0 | M20: 0 | N20: 0 | O20: 0 | P20: 0 | Q20: 0 | R20: 0 | S20: 0 | T20: 0 | U20: 0 | V20: =L10 | W20: =M10 | X20: =N10 | Y20: 0 | Z20: 0 | AA20: 0 | AG20: =INDEX(Global_Solver!$BC$5:$BC$52, 6*E5+1, 1) | AH20: =SUMPRODUCT(P20:AA20, AG14:AG25) | AI20: =SUMPRODUCT(D20:O20, AH14:AH25)-B32
D21: 0 | E21: =K15 | F21: 0 | G21: 0 | H21: 0 | I21: =K19 | J21: 0 | K21: =E15 | L21: 0 | M21: 0 | N21: 0 | O21: =-I15 | P21: 0 | Q21: 0 | R21: 0 | S21: 0 | T21: 0 | U21: 0 | V21: =L11 | W21: =M11 | X21: =N11 | Y21: 0 | Z21: 0 | AA21: 0 | AG21: =INDEX(Global_Solver!$BC$5:$BC$52, 6*E5+2, 1) | AH21: =SUMPRODUCT(P21:AA21, AG14:AG25) | AI21: =SUMPRODUCT(D21:O21, AH14:AH25)-B33
D22: 0 | E22: 0 | F22: =L16 | G22: 0 | H22: =L18 | I22: 0 | J22: 0 | K22: 0 | L22: =F16 | M22: 0 | N22: =-H16 | O22: 0 | P22: 0 | Q22: 0 | R22: 0 | S22: 0 | T22: 0 | U22: 0 | V22: =L12 | W22: =M12 | X22: =N12 | Y22: 0 | Z22: 0 | AA22: 0 | AG22: =INDEX(Global_Solver!$BC$5:$BC$52, 6*E5+3, 1) | AH22: =SUMPRODUCT(P22:AA22, AG14:AG25) | AI22: =SUMPRODUCT(D22:O22, AH14:AH25)-B34
D23: 0 | E23: 0 | F23: 0 | G23: =M17 | H23: 0 | I23: 0 | J23: 0 | K23: 0 | L23: 0 | M23: =-M17 | N23: 0 | O23: 0 | P23: 0 | Q23: 0 | R23: 0 | S23: 0 | T23: 0 | U23: 0 | V23: 0 | W23: 0 | X23: 0 | Y23: =L10 | Z23: =M10 | AA23: =N10 | AG23: =INDEX(Global_Solver!$BC$5:$BC$52, 6*E5+4, 1) | AH23: =SUMPRODUCT(P23:AA23, AG14:AG25) | AI23: =SUMPRODUCT(D23:O23, AH14:AH25)-B35
D24: 0 | E24: 0 | F24: =N16 | G24: 0 | H24: =N18 | I24: 0 | J24: 0 | K24: 0 | L24: =L22 | M24: 0 | N24: =H18 | O24: 0 | P24: 0 | Q24: 0 | R24: 0 | S24: 0 | T24: 0 | U24: 0 | V24: 0 | W24: 0 | X24: 0 | Y24: =L11 | Z24: =M11 | AA24: =N11 | AG24: =INDEX(Global_Solver!$BC$5:$BC$52, 6*E5+5, 1) | AH24: =SUMPRODUCT(P24:AA24, AG14:AG25) | AI24: =SUMPRODUCT(D24:O24, AH14:AH25)-B36
D25: 0 | E25: =O15 | F25: 0 | G25: 0 | H25: 0 | I25: =O19 | J25: 0 | K25: =K21 | L25: 0 | M25: 0 | N25: 0 | O25: =I19 | P25: 0 | Q25: 0 | R25: 0 | S25: 0 | T25: 0 | U25: 0 | V25: 0 | W25: 0 | X25: 0 | Y25: =L12 | Z25: =M12 | AA25: =N12 | AG25: =INDEX(Global_Solver!$BC$5:$BC$52, 6*E5+6, 1) | AH25: =SUMPRODUCT(P25:AA25, AG14:AG25) | AI25: =SUMPRODUCT(D25:O25, AH14:AH25)-B37
B26: =IF(C6,-C10*F12*E10*Inputs!$K$11,0) | C26: =SUMPRODUCT(P14:AA14, B26:B37) | D26: =SUMPRODUCT(D14:O14, P14:P25) | E26: =SUMPRODUCT(D14:O14, Q14:Q25) | F26: =SUMPRODUCT(D14:O14, R14:R25) | G26: =SUMPRODUCT(D14:O14, S14:S25) | H26: =SUMPRODUCT(D14:O14, T14:T25) | I26: =SUMPRODUCT(D14:O14, U14:U25) | J26: =SUMPRODUCT(D14:O14, V14:V25) | K26: =SUMPRODUCT(D14:O14, W14:W25) | L26: =SUMPRODUCT(D14:O14, X14:X25) | M26: =SUMPRODUCT(D14:O14, Y14:Y25) | N26: =SUMPRODUCT(D14:O14, Z14:Z25) | O26: =SUMPRODUCT(D14:O14, AA14:AA25) | P26: =SUMPRODUCT(P14:AA14, D26:D37) | Q26: =SUMPRODUCT(P14:AA14, E26:E37) | R26: =SUMPRODUCT(P14:AA14, F26:F37) | S26: =SUMPRODUCT(P14:AA14, G26:G37) | T26: =SUMPRODUCT(P14:AA14, H26:H37) | U26: =SUMPRODUCT(P14:AA14, I26:I37) | V26: =SUMPRODUCT(P14:AA14, J26:J37) | W26: =SUMPRODUCT(P14:AA14, K26:K37) | X26: =SUMPRODUCT(P14:AA14, L26:L37) | Y26: =SUMPRODUCT(P14:AA14, M26:M37) | Z26: =SUMPRODUCT(P14:AA14, N26:N37) | AA26: =SUMPRODUCT(P14:AA14, O26:O37)
B27: 0 | C27: =SUMPRODUCT(P15:AA15, B26:B37) | D27: =SUMPRODUCT(D15:O15, P14:P25) | E27: =SUMPRODUCT(D15:O15, Q14:Q25) | F27: =SUMPRODUCT(D15:O15, R14:R25) | G27: =SUMPRODUCT(D15:O15, S14:S25) | H27: =SUMPRODUCT(D15:O15, T14:T25) | I27: =SUMPRODUCT(D15:O15, U14:U25) | J27: =SUMPRODUCT(D15:O15, V14:V25) | K27: =SUMPRODUCT(D15:O15, W14:W25) | L27: =SUMPRODUCT(D15:O15, X14:X25) | M27: =SUMPRODUCT(D15:O15, Y14:Y25) | N27: =SUMPRODUCT(D15:O15, Z14:Z25) | O27: =SUMPRODUCT(D15:O15, AA14:AA25) | P27: =SUMPRODUCT(P15:AA15, D26:D37) | Q27: =SUMPRODUCT(P15:AA15, E26:E37) | R27: =SUMPRODUCT(P15:AA15, F26:F37) | S27: =SUMPRODUCT(P15:AA15, G26:G37) | T27: =SUMPRODUCT(P15:AA15, H26:H37) | U27: =SUMPRODUCT(P15:AA15, I26:I37) | V27: =SUMPRODUCT(P15:AA15, J26:J37) | W27: =SUMPRODUCT(P15:AA15, K26:K37) | X27: =SUMPRODUCT(P15:AA15, L26:L37) | Y27: =SUMPRODUCT(P15:AA15, M26:M37) | Z27: =SUMPRODUCT(P15:AA15, N26:N37) | AA27: =SUMPRODUCT(P15:AA15, O26:O37)
B28: 0 | C28: =SUMPRODUCT(P16:AA16, B26:B37) | D28: =SUMPRODUCT(D16:O16, P14:P25) | E28: =SUMPRODUCT(D16:O16, Q14:Q25) | F28: =SUMPRODUCT(D16:O16, R14:R25) | G28: =SUMPRODUCT(D16:O16, S14:S25) | H28: =SUMPRODUCT(D16:O16, T14:T25) | I28: =SUMPRODUCT(D16:O16, U14:U25) | J28: =SUMPRODUCT(D16:O16, V14:V25) | K28: =SUMPRODUCT(D16:O16, W14:W25) | L28: =SUMPRODUCT(D16:O16, X14:X25) | M28: =SUMPRODUCT(D16:O16, Y14:Y25) | N28: =SUMPRODUCT(D16:O16, Z14:Z25) | O28: =SUMPRODUCT(D16:O16, AA14:AA25) | P28: =SUMPRODUCT(P16:AA16, D26:D37) | Q28: =SUMPRODUCT(P16:AA16, E26:E37) | R28: =SUMPRODUCT(P16:AA16, F26:F37) | S28: =SUMPRODUCT(P16:AA16, G26:G37) | T28: =SUMPRODUCT(P16:AA16, H26:H37) | U28: =SUMPRODUCT(P16:AA16, I26:I37) | V28: =SUMPRODUCT(P16:AA16, J26:J37) | W28: =SUMPRODUCT(P16:AA16, K26:K37) | X28: =SUMPRODUCT(P16:AA16, L26:L37) | Y28: =SUMPRODUCT(P16:AA16, M26:M37) | Z28: =SUMPRODUCT(P16:AA16, N26:N37) | AA28: =SUMPRODUCT(P16:AA16, O26:O37)
B29: 0 | C29: =SUMPRODUCT(P17:AA17, B26:B37) | D29: =SUMPRODUCT(D17:O17, P14:P25) | E29: =SUMPRODUCT(D17:O17, Q14:Q25) | F29: =SUMPRODUCT(D17:O17, R14:R25) | G29: =SUMPRODUCT(D17:O17, S14:S25) | H29: =SUMPRODUCT(D17:O17, T14:T25) | I29: =SUMPRODUCT(D17:O17, U14:U25) | J29: =SUMPRODUCT(D17:O17, V14:V25) | K29: =SUMPRODUCT(D17:O17, W14:W25) | L29: =SUMPRODUCT(D17:O17, X14:X25) | M29: =SUMPRODUCT(D17:O17, Y14:Y25) | N29: =SUMPRODUCT(D17:O17, Z14:Z25) | O29: =SUMPRODUCT(D17:O17, AA14:AA25) | P29: =SUMPRODUCT(P17:AA17, D26:D37) | Q29: =SUMPRODUCT(P17:AA17, E26:E37) | R29: =SUMPRODUCT(P17:AA17, F26:F37) | S29: =SUMPRODUCT(P17:AA17, G26:G37) | T29: =SUMPRODUCT(P17:AA17, H26:H37) | U29: =SUMPRODUCT(P17:AA17, I26:I37) | V29: =SUMPRODUCT(P17:AA17, J26:J37) | W29: =SUMPRODUCT(P17:AA17, K26:K37) | X29: =SUMPRODUCT(P17:AA17, L26:L37) | Y29: =SUMPRODUCT(P17:AA17, M26:M37) | Z29: =SUMPRODUCT(P17:AA17, N26:N37) | AA29: =SUMPRODUCT(P17:AA17, O26:O37)
B30: 0 | C30: =SUMPRODUCT(P18:AA18, B26:B37) | D30: =SUMPRODUCT(D18:O18, P14:P25) | E30: =SUMPRODUCT(D18:O18, Q14:Q25) | F30: =SUMPRODUCT(D18:O18, R14:R25) | G30: =SUMPRODUCT(D18:O18, S14:S25) | H30: =SUMPRODUCT(D18:O18, T14:T25) | I30: =SUMPRODUCT(D18:O18, U14:U25) | J30: =SUMPRODUCT(D18:O18, V14:V25) | K30: =SUMPRODUCT(D18:O18, W14:W25) | L30: =SUMPRODUCT(D18:O18, X14:X25) | M30: =SUMPRODUCT(D18:O18, Y14:Y25) | N30: =SUMPRODUCT(D18:O18, Z14:Z25) | O30: =SUMPRODUCT(D18:O18, AA14:AA25) | P30: =SUMPRODUCT(P18:AA18, D26:D37) | Q30: =SUMPRODUCT(P18:AA18, E26:E37) | R30: =SUMPRODUCT(P18:AA18, F26:F37) | S30: =SUMPRODUCT(P18:AA18, G26:G37) | T30: =SUMPRODUCT(P18:AA18, H26:H37) | U30: =SUMPRODUCT(P18:AA18, I26:I37) | V30: =SUMPRODUCT(P18:AA18, J26:J37) | W30: =SUMPRODUCT(P18:AA18, K26:K37) | X30: =SUMPRODUCT(P18:AA18, L26:L37) | Y30: =SUMPRODUCT(P18:AA18, M26:M37) | Z30: =SUMPRODUCT(P18:AA18, N26:N37) | AA30: =SUMPRODUCT(P18:AA18, O26:O37)
B31: 0 | C31: =SUMPRODUCT(P19:AA19, B26:B37) | D31: =SUMPRODUCT(D19:O19, P14:P25) | E31: =SUMPRODUCT(D19:O19, Q14:Q25) | F31: =SUMPRODUCT(D19:O19, R14:R25) | G31: =SUMPRODUCT(D19:O19, S14:S25) | H31: =SUMPRODUCT(D19:O19, T14:T25) | I31: =SUMPRODUCT(D19:O19, U14:U25) | J31: =SUMPRODUCT(D19:O19, V14:V25) | K31: =SUMPRODUCT(D19:O19, W14:W25) | L31: =SUMPRODUCT(D19:O19, X14:X25) | M31: =SUMPRODUCT(D19:O19, Y14:Y25) | N31: =SUMPRODUCT(D19:O19, Z14:Z25) | O31: =SUMPRODUCT(D19:O19, AA14:AA25) | P31: =SUMPRODUCT(P19:AA19, D26:D37) | Q31: =SUMPRODUCT(P19:AA19, E26:E37) | R31: =SUMPRODUCT(P19:AA19, F26:F37) | S31: =SUMPRODUCT(P19:AA19, G26:G37) | T31: =SUMPRODUCT(P19:AA19, H26:H37) | U31: =SUMPRODUCT(P19:AA19, I26:I37) | V31: =SUMPRODUCT(P19:AA19, J26:J37) | W31: =SUMPRODUCT(P19:AA19, K26:K37) | X31: =SUMPRODUCT(P19:AA19, L26:L37) | Y31: =SUMPRODUCT(P19:AA19, M26:M37) | Z31: =SUMPRODUCT(P19:AA19, N26:N37) | AA31: =SUMPRODUCT(P19:AA19, O26:O37)
B32: =IF(C6,C10*F12*E10*Inputs!$K$11,0) | C32: =SUMPRODUCT(P20:AA20, B26:B37) | D32: =SUMPRODUCT(D20:O20, P14:P25) | E32: =SUMPRODUCT(D20:O20, Q14:Q25) | F32: =SUMPRODUCT(D20:O20, R14:R25) | G32: =SUMPRODUCT(D20:O20, S14:S25) | H32: =SUMPRODUCT(D20:O20, T14:T25) | I32: =SUMPRODUCT(D20:O20, U14:U25) | J32: =SUMPRODUCT(D20:O20, V14:V25) | K32: =SUMPRODUCT(D20:O20, W14:W25) | L32: =SUMPRODUCT(D20:O20, X14:X25) | M32: =SUMPRODUCT(D20:O20, Y14:Y25) | N32: =SUMPRODUCT(D20:O20, Z14:Z25) | O32: =SUMPRODUCT(D20:O20, AA14:AA25) | P32: =SUMPRODUCT(P20:AA20, D26:D37) | Q32: =SUMPRODUCT(P20:AA20, E26:E37) | R32: =SUMPRODUCT(P20:AA20, F26:F37) | S32: =SUMPRODUCT(P20:AA20, G26:G37) | T32: =SUMPRODUCT(P20:AA20, H26:H37) | U32: =SUMPRODUCT(P20:AA20, I26:I37) | V32: =SUMPRODUCT(P20:AA20, J26:J37) | W32: =SUMPRODUCT(P20:AA20, K26:K37) | X32: =SUMPRODUCT(P20:AA20, L26:L37) | Y32: =SUMPRODUCT(P20:AA20, M26:M37) | Z32: =SUMPRODUCT(P20:AA20, N26:N37) | AA32: =SUMPRODUCT(P20:AA20, O26:O37)
B33: 0 | C33: =SUMPRODUCT(P21:AA21, B26:B37) | D33: =SUMPRODUCT(D21:O21, P14:P25) | E33: =SUMPRODUCT(D21:O21, Q14:Q25) | F33: =SUMPRODUCT(D21:O21, R14:R25) | G33: =SUMPRODUCT(D21:O21, S14:S25) | H33: =SUMPRODUCT(D21:O21, T14:T25) | I33: =SUMPRODUCT(D21:O21, U14:U25) | J33: =SUMPRODUCT(D21:O21, V14:V25) | K33: =SUMPRODUCT(D21:O21, W14:W25) | L33: =SUMPRODUCT(D21:O21, X14:X25) | M33: =SUMPRODUCT(D21:O21, Y14:Y25) | N33: =SUMPRODUCT(D21:O21, Z14:Z25) | O33: =SUMPRODUCT(D21:O21, AA14:AA25) | P33: =SUMPRODUCT(P21:AA21, D26:D37) | Q33: =SUMPRODUCT(P21:AA21, E26:E37) | R33: =SUMPRODUCT(P21:AA21, F26:F37) | S33: =SUMPRODUCT(P21:AA21, G26:G37) | T33: =SUMPRODUCT(P21:AA21, H26:H37) | U33: =SUMPRODUCT(P21:AA21, I26:I37) | V33: =SUMPRODUCT(P21:AA21, J26:J37) | W33: =SUMPRODUCT(P21:AA21, K26:K37) | X33: =SUMPRODUCT(P21:AA21, L26:L37) | Y33: =SUMPRODUCT(P21:AA21, M26:M37) | Z33: =SUMPRODUCT(P21:AA21, N26:N37) | AA33: =SUMPRODUCT(P21:AA21, O26:O37)
B34: 0 | C34: =SUMPRODUCT(P22:AA22, B26:B37) | D34: =SUMPRODUCT(D22:O22, P14:P25) | E34: =SUMPRODUCT(D22:O22, Q14:Q25) | F34: =SUMPRODUCT(D22:O22, R14:R25) | G34: =SUMPRODUCT(D22:O22, S14:S25) | H34: =SUMPRODUCT(D22:O22, T14:T25) | I34: =SUMPRODUCT(D22:O22, U14:U25) | J34: =SUMPRODUCT(D22:O22, V14:V25) | K34: =SUMPRODUCT(D22:O22, W14:W25) | L34: =SUMPRODUCT(D22:O22, X14:X25) | M34: =SUMPRODUCT(D22:O22, Y14:Y25) | N34: =SUMPRODUCT(D22:O22, Z14:Z25) | O34: =SUMPRODUCT(D22:O22, AA14:AA25) | P34: =SUMPRODUCT(P22:AA22, D26:D37) | Q34: =SUMPRODUCT(P22:AA22, E26:E37) | R34: =SUMPRODUCT(P22:AA22, F26:F37) | S34: =SUMPRODUCT(P22:AA22, G26:G37) | T34: =SUMPRODUCT(P22:AA22, H26:H37) | U34: =SUMPRODUCT(P22:AA22, I26:I37) | V34: =SUMPRODUCT(P22:AA22, J26:J37) | W34: =SUMPRODUCT(P22:AA22, K26:K37) | X34: =SUMPRODUCT(P22:AA22, L26:L37) | Y34: =SUMPRODUCT(P22:AA22, M26:M37) | Z34: =SUMPRODUCT(P22:AA22, N26:N37) | AA34: =SUMPRODUCT(P22:AA22, O26:O37)
B35: 0 | C35: =SUMPRODUCT(P23:AA23, B26:B37) | D35: =SUMPRODUCT(D23:O23, P14:P25) | E35: =SUMPRODUCT(D23:O23, Q14:Q25) | F35: =SUMPRODUCT(D23:O23, R14:R25) | G35: =SUMPRODUCT(D23:O23, S14:S25) | H35: =SUMPRODUCT(D23:O23, T14:T25) | I35: =SUMPRODUCT(D23:O23, U14:U25) | J35: =SUMPRODUCT(D23:O23, V14:V25) | K35: =SUMPRODUCT(D23:O23, W14:W25) | L35: =SUMPRODUCT(D23:O23, X14:X25) | M35: =SUMPRODUCT(D23:O23, Y14:Y25) | N35: =SUMPRODUCT(D23:O23, Z14:Z25) | O35: =SUMPRODUCT(D23:O23, AA14:AA25) | P35: =SUMPRODUCT(P23:AA23, D26:D37) | Q35: =SUMPRODUCT(P23:AA23, E26:E37) | R35: =SUMPRODUCT(P23:AA23, F26:F37) | S35: =SUMPRODUCT(P23:AA23, G26:G37) | T35: =SUMPRODUCT(P23:AA23, H26:H37) | U35: =SUMPRODUCT(P23:AA23, I26:I37) | V35: =SUMPRODUCT(P23:AA23, J26:J37) | W35: =SUMPRODUCT(P23:AA23, K26:K37) | X35: =SUMPRODUCT(P23:AA23, L26:L37) | Y35: =SUMPRODUCT(P23:AA23, M26:M37) | Z35: =SUMPRODUCT(P23:AA23, N26:N37) | AA35: =SUMPRODUCT(P23:AA23, O26:O37)
B36: 0 | C36: =SUMPRODUCT(P24:AA24, B26:B37) | D36: =SUMPRODUCT(D24:O24, P14:P25) | E36: =SUMPRODUCT(D24:O24, Q14:Q25) | F36: =SUMPRODUCT(D24:O24, R14:R25) | G36: =SUMPRODUCT(D24:O24, S14:S25) | H36: =SUMPRODUCT(D24:O24, T14:T25) | I36: =SUMPRODUCT(D24:O24, U14:U25) | J36: =SUMPRODUCT(D24:O24, V14:V25) | K36: =SUMPRODUCT(D24:O24, W14:W25) | L36: =SUMPRODUCT(D24:O24, X14:X25) | M36: =SUMPRODUCT(D24:O24, Y14:Y25) | N36: =SUMPRODUCT(D24:O24, Z14:Z25) | O36: =SUMPRODUCT(D24:O24, AA14:AA25) | P36: =SUMPRODUCT(P24:AA24, D26:D37) | Q36: =SUMPRODUCT(P24:AA24, E26:E37) | R36: =SUMPRODUCT(P24:AA24, F26:F37) | S36: =SUMPRODUCT(P24:AA24, G26:G37) | T36: =SUMPRODUCT(P24:AA24, H26:H37) | U36: =SUMPRODUCT(P24:AA24, I26:I37) | V36: =SUMPRODUCT(P24:AA24, J26:J37) | W36: =SUMPRODUCT(P24:AA24, K26:K37) | X36: =SUMPRODUCT(P24:AA24, L26:L37) | Y36: =SUMPRODUCT(P24:AA24, M26:M37) | Z36: =SUMPRODUCT(P24:AA24, N26:N37) | AA36: =SUMPRODUCT(P24:AA24, O26:O37)
B37: 0 | C37: =SUMPRODUCT(P25:AA25, B26:B37) | D37: =SUMPRODUCT(D25:O25, P14:P25) | E37: =SUMPRODUCT(D25:O25, Q14:Q25) | F37: =SUMPRODUCT(D25:O25, R14:R25) | G37: =SUMPRODUCT(D25:O25, S14:S25) | H37: =SUMPRODUCT(D25:O25, T14:T25) | I37: =SUMPRODUCT(D25:O25, U14:U25) | J37: =SUMPRODUCT(D25:O25, V14:V25) | K37: =SUMPRODUCT(D25:O25, W14:W25) | L37: =SUMPRODUCT(D25:O25, X14:X25) | M37: =SUMPRODUCT(D25:O25, Y14:Y25) | N37: =SUMPRODUCT(D25:O25, Z14:Z25) | O37: =SUMPRODUCT(D25:O25, AA14:AA25) | P37: =SUMPRODUCT(P25:AA25, D26:D37) | Q37: =SUMPRODUCT(P25:AA25, E26:E37) | R37: =SUMPRODUCT(P25:AA25, F26:F37) | S37: =SUMPRODUCT(P25:AA25, G26:G37) | T37: =SUMPRODUCT(P25:AA25, H26:H37) | U37: =SUMPRODUCT(P25:AA25, I26:I37) | V37: =SUMPRODUCT(P25:AA25, J26:J37) | W37: =SUMPRODUCT(P25:AA25, K26:K37) | X37: =SUMPRODUCT(P25:AA25, L26:L37) | Y37: =SUMPRODUCT(P25:AA25, M26:M37) | Z37: =SUMPRODUCT(P25:AA25, N26:N37) | AA37: =SUMPRODUCT(P25:AA25, O26:O37)
B39: ELEMENT 1 ANALYSIS BLOCK
B40: Node A ID | C40: =Inputs!C30 | D40: Node B ID | E40: =Inputs!D30
B41: Is Active? | C41: =AND(C40<>"",E40<>"")
B42: Node A Coord | C42: =IF(C41,VLOOKUP(C40,Inputs!$B$17:$E$24,2,FALSE),0.0) | D42: =IF(C41,VLOOKUP(C40,Inputs!$B$17:$E$24,3,FALSE),0.0) | E42: =IF(C41,VLOOKUP(C40,Inputs!$B$17:$E$24,4,FALSE),0.0) | F42: Node B Coord | G42: =IF(C41,VLOOKUP(E40,Inputs!$B$17:$E$24,2,FALSE),0.0) | H42: =IF(C41,VLOOKUP(E40,Inputs!$B$17:$E$24,3,FALSE),0.0) | I42: =IF(C41,VLOOKUP(E40,Inputs!$B$17:$E$24,4,FALSE),0.0)
B43: deltas dx,dy,dz | C43: =G42-C42 | D43: =H42-D42 | E43: =I42-E42 | F43: Length L | G43: =IF(C41,SQRT(C43^2+D43^2+E43^2),1.0)
...

Sheet Global_Solver
B2: Global Assembly, Boundary Conditions, and Linear Equation Solver
C4: N0_tx | D4: N0_ty | E4: N0_tz | F4: N0_rx | G4: N0_ry | H4: N0_rz | I4: N1_tx | J4: N1_ty | K4: N1_tz | L4: N1_rx | M4: N1_ry | N4: N1_rz | O4: N2_tx | P4: N2_ty | Q4: N2_tz | R4: N2_rx | S4: N2_ry | T4: N2_rz | U4: N3_tx | V4: N3_ty | W4: N3_tz | X4: N3_rx | Y4: N3_ry | Z4: N3_rz | AA4: N4_tx | AB4: N4_ty | AC4: N4_tz | AD4: N4_rx | AE4: N4_ry | AF4: N4_rz | AG4: N5_tx | AH4: N5_ty | AI4: N5_tz | AJ4: N5_rx | AK4: N5_ry | AL4: N5_rz | AM4: N6_tx | AN4: N6_ty | AO4: N6_tz | AP4: N6_rx | AQ4: N6_ry | AR4: N6_rz | AS4: N7_tx | AT4: N7_ty | AU4: N7_tz | AV4: N7_rx | AW4: N7_ry | AX4: N7_rz | AY4: F_Weight (N) | AZ4: F_Thermal (N) | BB4: u_Weight (m) | BC4: u_Thermal (m)
